Workbook

Sheet Resumen
A2: DIARCO · Implementación Bloque 1
A4: Objetivo vigente | B4: Desde 04/11: módulos productivos, smoke y paralelo
A5: Autoridad en paralelo | B5: La información DIARCO/SGM sigue siendo válida
A6: Estado del kit | B6: Propuesta. Sin ejecución ni aceptación acreditadas
A8: Indicador de preparación | B8: Cantidad
A9: Frentes B1 planificados | B9: =COUNTA(Asignaciones!A6:A15) -> 10
A10: Equipos con compromiso nominal | B10: =COUNTIF(Asignaciones!O6:O15,"Equipo confirmado") -> 0
A11: Actividades WBS propuestas | B11: =COUNTA(WBS!A6:A121) -> 116
A12: Actividades con cierre documentado | B12: =COUNTIF(WBS!P6:P121,"Cierre documentado") -> 0
A13: Registros UAT/smoke | B13: =COUNTA(UAT!A6:A38) -> 33
A14: Ejecuciones aceptadas con evidencia | B14: =COUNTIF(UAT!V6:V38,"Ejecución aceptada") -> 0
A15: Registros de formación por evaluar | B15: =COUNTIF(Formacion!H6:H28,"No evaluado") -> 23
A16: Decisiones aún sin resolver | B16: =COUNTIF(Decisiones!E6:E19,"Sin decidir")+COUNTIF(Decisiones!E6:E19,"En análisis") -> 14
A19: Próximo paso de Dirección | B19: Confirmar personas, horas y población del paralelo
A21: Uso del libro | B21: Amarillo = entrada humana. Fórmulas = control documental, no aprobación automática.
B22: UAT: conservar ejecuciones y repruebas. OC paralelo: duplicar bloque por OC/línea.
B23: Las nuevas tareas WBS están al final de la tabla; filtrar por ID/predecesoras para planificar.
B24: Los indicadores iniciales muestran preparación pendiente, no porcentajes de avance histórico.
B25: Un gate requiere firma humana y evidencia, aunque los controles documentales estén completos.

Sheet Asignaciones
A2: Equipo por capacidad
A3: Amarillo: completar. Los nombres de antecedentes no equivalen a una designación aceptada.
A5: ID | B5: Capacidad B1 | C5: Bloque | D5: Dueño propuesto (función) | E5: Interlocutor de antecedentes | F5: Titular confirmado | G5: Suplente confirmado | H5: Jefatura que libera tiempo | I5: h titular/semana | J5: h suplente/semana | K5: Ventanas de agenda | L5: Compromiso | M5: Acepta jefatura | N5: Fecha aceptación | O5: Preparación del equipo | P5: Dueño nominal confirmado | Q5: Aceptación del dueño
A6: M01 | B6: Catálogo y maestros | C6: B1 | D6: Dueño de Datos Maestros | E6: Guillermo Alvez (Auditoría); designar Administración de Datos Maestros | L6: Sin confirmar | O6: =IF(C6<>"B1","Fuera de B1",IF(AND(F6<>"",G6<>"",H6<>"",ISNUMBER(I6),I6>0,ISNUMBER(J6),J6>0,K6<>"",L6="Confirmado",M6<>"",ISNUMBER(N6),P6<>"",Q6="Confirmado"),"Equipo confirmado","Falta compromiso nominal")) -> Falta compromiso nominal | Q6: Sin confirmar
A7: M02 | B7: Surtido, clusters y segmentos | C7: B1 | D7: Dueño de Surtido | E7: Liliana D'Amico (sugerida por antecedentes) | F7: Liliana D'Amico | L7: Sin confirmar | O7: =IF(C7<>"B1","Fuera de B1",IF(AND(F7<>"",G7<>"",H7<>"",ISNUMBER(I7),I7>0,ISNUMBER(J7),J7>0,K7<>"",L7="Confirmado",M7<>"",ISNUMBER(N7),P7<>"",Q7="Confirmado"),"Equipo confirmado","Falta compromiso nominal")) -> Falta compromiso nominal | Q7: Sin confirmar
A8: M03 | B8: Listas y acuerdos comerciales de compra | C8: B1 | D8: Dueño de Compras | E8: Sebastián Basconcelos (según minuta 13/10; confirmar designación) | F8: Sebastián Basconcelos | L8: Sin confirmar | O8: =IF(C8<>"B1","Fuera de B1",IF(AND(F8<>"",G8<>"",H8<>"",ISNUMBER(I8),I8>0,ISNUMBER(J8),J8>0,K8<>"",L8="Confirmado",M8<>"",ISNUMBER(N8),P8<>"",Q8="Confirmado"),"Equipo confirmado","Falta compromiso nominal")) -> Falta compromiso nominal | Q8: Sin confirmar
A9: M04 | B9: Forecast y compra inteligente/directa | C9: B1 | D9: Dueño de Abastecimiento | E9: Romina Garfi, Carolina Tavernisse(Non-Food), Camila Klipauka(Perfumeria),Marcelo Cingolani, Diego Baldi(Perecederos), Paloma Romero (Barrio) | F9: Romina Garfi, Carolina Tavernisse(Non-Food),Diego Baldi(Perecederos), Paloma Romero | G9: Camila Klipauka(Perfumeria),Marcelo Cingolani, | L9: Sin confirmar | O9: =IF(C9<>"B1","Fuera de B1",IF(AND(F9<>"",G9<>"",H9<>"",ISNUMBER(I9),I9>0,ISNUMBER(J9),J9>0,K9<>"",L9="Confirmado",M9<>"",ISNUMBER(N9),P9<>"",Q9="Confirmado"),"Equipo confirmado","Falta compromiso nominal")) -> Falta compromiso nominal | Q9: Sin confirmar
A10: M05 | B10: Órdenes de compra e integración SGM | C10: B1 | D10: Dueño de Compras | E10: Romina Garfi, Carolina Tavernisse(Non-Food), Camila Klipauka(Perfumeria),Marcelo Cingolani, Diego Baldi(Perecederos), Paloma Romero (Barrio) | F10: Romina Garfi, Carolina Tavernisse(Non-Food), Camila Klipauka(Perfumeria),Marcelo Cingolani, Diego Baldi(Perecederos), Paloma Romero | L10: Sin confirmar | O10: =IF(C10<>"B1","Fuera de B1",IF(AND(F10<>"",G10<>"",H10<>"",ISNUMBER(I10),I10>0,ISNUMBER(J10),J10>0,K10<>"",L10="Confirmado",M10<>"",ISNUMBER(N10),P10<>"",Q10="Confirmado"),"Equipo confirmado","Falta compromiso nominal")) -> Falta compromiso nominal | Q10: Sin confirmar
A11: M06 | B11: Recepción en sucursal y convivencia SGM | C11: B1 | D11: Dueño de Operaciones de Sucursal | E11: Fernando Ureña / Cecilia Camus / Javier Dafonte / Rodolfo Herlein (elegir titular) | F11: Fernando Ureña / Cecilia Camus / Javier Dafonte / Rodolfo Herlein | L11: Sin confirmar | O11: =IF(C11<>"B1","Fuera de B1",IF(AND(F11<>"",G11<>"",H11<>"",ISNUMBER(I11),I11>0,ISNUMBER(J11),J11>0,K11<>"",L11="Confirmado",M11<>"",ISNUMBER(N11),P11<>"",Q11="Confirmado"),"Equipo confirmado","Falta compromiso nominal")) -> Falta compromiso nominal | Q11: Sin confirmar
A12: M07 | B12: Inventarios y ajustes | C12: B1 | D12: Dueño de Control de Inventarios | E12: Guillermo Alvez /Javier Dafonte | F12: Guillermo Alvez | L12: Sin confirmar | O12: =IF(C12<>"B1","Fuera de B1",IF(AND(F12<>"",G12<>"",H12<>"",ISNUMBER(I12),I12>0,ISNUMBER(J12),J12>0,K12<>"",L12="Confirmado",M12<>"",ISNUMBER(N12),P12<>"",Q12="Confirmado"),"Equipo confirmado","Falta compromiso nominal")) -> Falta compromiso nominal | Q12: Sin confirmar
A13: M08 | B13: PDD y necesidades de distribución | C13: B1 | D13: Dueño de Planificación Logística | E13: Christian Rojas (logistica)/ Liliana D'Amico, Carolina Tavernisse ( Compras) | F13: Christian Rojas (logistica)/ Liliana D'Amico, Carolina Tavernisse | L13: Sin confirmar | O13: =IF(C13<>"B1","Fuera de B1",IF(AND(F13<>"",G13<>"",H13<>"",ISNUMBER(I13),I13>0,ISNUMBER(J13),J13>0,K13<>"",L13="Confirmado",M13<>"",ISNUMBER(N13),P13<>"",Q13="Confirmado"),"Equipo confirmado","Falta compromiso nominal")) -> Falta compromiso nominal | Q13: Sin confirmar
A14: M09 | B14: Transferencias y distribución con Valkimia | C14: B1 | D14: Dueño de Distribución | E14: Christian Rojas / Gastón (Logística), enlace Comercial a designar | F14: Christian Rojas / Gastón | L14: Sin confirmar | O14: =IF(C14<>"B1","Fuera de B1",IF(AND(F14<>"",G14<>"",H14<>"",ISNUMBER(I14),I14>0,ISNUMBER(J14),J14>0,K14<>"",L14="Confirmado",M14<>"",ISNUMBER(N14),P14<>"",Q14="Confirmado"),"Equipo confirmado","Falta compromiso nominal")) -> Falta compromiso nominal | Q14: Sin confirmar
A15: M10 | B15: Stock, conciliación y observabilidad | C15: B1 | D15: Dueño de Operación y Control de Stock | E15: IT + Control de Stock Hernan López Lider SGM DIARCO) | F15: IT + Control | L15: Sin confirmar | O15: =IF(C15<>"B1","Fuera de B1",IF(AND(F15<>"",G15<>"",H15<>"",ISNUMBER(I15),I15>0,ISNUMBER(J15),J15>0,K15<>"",L15="Confirmado",M15<>"",ISNUMBER(N15),P15<>"",Q15="Confirmado"),"Equipo confirmado","Falta compromiso nominal")) -> Falta compromiso nominal | Q15: Sin confirmar

Sheet WBS
A2: Plan de ejecución del Bloque 1
A3: Filtrar por módulo/oleada. Fechas propuestas, sin ejecución acreditada. G1/G2 se instancian por población seleccionada.
A5: WBS | B5: Módulo | C5: Actividad | D5: Entregable / acción concreta | E5: R | F5: A | G5: Predecesoras | H5: Ventana propuesta | I5: Criterio de cierre | J5: Estado | K5: Nombre ejecutor R | L5: Fecha objetivo | M5: Evidencia | N5: Aceptado por | O5: Fecha aceptación | P5: Control de cierre
A6: 1.01 | B6: TRANSVERSAL | C6: Conciliar alcance y GAPS | D6: Baseline por capacidad con B1/B2/B3/pendiente, motivo y fuente | E6: LZ | F6: SP | H6: Preparación / G0 | I6: Cada capacidad tiene decisión o bloqueo explícito. No se interpreta silencio como aprobación. | J6: Propuesto | P6: =IF(J6="Cerrado",IF(AND(K6<>"",M6<>"",N6<>"",ISNUMBER(O6)),"Cierre documentado","Falta evidencia o aceptación"),"Pendiente") -> Pendiente
A7: 1.02 | B7: TRANSVERSAL | C7: Nombrar sponsor y líder DIARCO | D7: Acta con nombres, facultades y suplencias | E7: LD | F7: SP | G7: 1.01 | H7: Lunes 02/11 propuesto | I7: Designaciones aceptadas por personas y jefaturas. | J7: Propuesto | P7: =IF(J7="Cerrado",IF(AND(K7<>"",M7<>"",N7<>"",ISNUMBER(O7)),"Cierre documentado","Falta evidencia o aceptación"),"Pendiente") -> Pendiente
A8: 1.03 | B8: TRANSVERSAL | C8: Asignar titulares y suplentes por módulo | D8: Fichas nominales y tiempo protegido | E8: LD | F8: SP | G8: 1.02 | H8: Lunes 02/11 propuesto | I8: Cada módulo B1 tiene dueño, referente, suplente y horas autorizadas. | J8: Propuesto | P8: =IF(J8="Cerrado",IF(AND(K8<>"",M8<>"",N8<>"",ISNUMBER(O8)),"Cierre documentado","Falta evidencia o aceptación"),"Pendiente") -> Pendiente
A9: 1.04 | B9: TRANSVERSAL | C9: Incorporar mesa de ayuda, IT y terceros | D9: Mapa de servicios, contactos, horario y escalamiento | E9: LD | F9: SP | G9: 1.02 | H9: Semana 1 | I9: Responsables y suplentes aceptan cobertura y simulacro. | J9: Propuesto | P9: =IF(J9="Cerrado",IF(AND(K9<>"",M9<>"",N9<>"",ISNUMBER(O9)),"Cierre documentado","Falta evidencia o aceptación"),"Pendiente") -> Pendiente
A10: 1.05 | B10: TRANSVERSAL | C10: Definir piloto, volumen y calendario | D10: Lista de usuarios/sitios/proveedores/casos, duración y exclusiones | E10: LD | F10: SP | G10: 1.01;1.03;1.04 | H10: Semana 1 | I10: Población, cobertura de excepciones y fechas acordadas con capacidad disponible. | J10: Propuesto | P10: =IF(J10="Cerrado",IF(AND(K10<>"",M10<>"",N10<>"",ISNUMBER(O10)),"Cierre documentado","Falta evidencia o aceptación"),"Pendiente") -> Pendiente
A11: 1.06 | B11: TRANSVERSAL | C11: Aprobar reglas de gobierno y G0 | D11: Acta de inicio y decisiones abiertas | E11: LD | F11: SP | G11: 1.01;1.02;1.03;1.04;1.05 | H11: Semana 1 / G0 | I11: Alcance, personas, capacidad, piloto y canal de decisiones registrados. | J11: Propuesto | P11: =IF(J11="Cerrado",IF(AND(K11<>"",M11<>"",N11<>"",ISNUMBER(O11)),"Cierre documentado","Falta evidencia o aceptación"),"Pendiente") -> Pendiente
A12: 2.01 | B12: TRANSVERSAL | C12: Relevar proceso actual y futuro | D12: Mapa extremo a extremo con cambios por rol | E12: RF | F12: DP | G12: 1.06 | H12: Antes de cada módulo | I12: Cada actividad, control y excepción tiene dueño. | J12: Propuesto | P12: =IF(J12="Cerrado",IF(AND(K12<>"",M12<>"",N12<>"",ISNUMBER(O12)),"Cierre documentado","Falta evidencia o aceptación"),"Pendiente") -> Pendiente
A13: 2.02 | B13: TRANSVERSAL | C13: Acordar maestría y convivencia SGM | D13: Matriz entidad/operación/sistema autorizado por etapa | E13: IT | F13: DP | G13: 2.01 | H13: Antes de cada módulo | I13: Un solo escritor autorizado por entidad y etapa. Emisor al proveedor definido. | J13: Propuesto | P13: =IF(J13="Cerrado",IF(AND(K13<>"",M13<>"",N13<>"",ISNUMBER(O13)),"Cierre documentado","Falta evidencia o aceptación"),"Pendiente") -> Pendiente
A14: 2.03 | B14: TRANSVERSAL | C14: Preparar ambientes, roles y accesos | D14: Accesos probados con segregación y versión identificada | E14: IT | F14: IT | G14: 1.06 | H14: Semana 1 y antes de cada prueba | I14: Usuarios entran y permisos positivos/negativos funcionan. | J14: Propuesto | P14: =IF(J14="Cerrado",IF(AND(K14<>"",M14<>"",N14<>"",ISNUMBER(O14)),"Cierre documentado","Falta evidencia o aceptación"),"Pendiente") -> Pendiente
A15: 2.04 | B15: TRANSVERSAL | C15: Fijar datos y resultados esperados | D15: Dataset versionado y casos dorados aprobados | E15: RF | F15: DP | G15: 2.01;2.02;2.03 | H15: Antes de UAT | I15: Cantidad/valor/regla esperados definidos por negocio, no sólo por el sistema. | J15: Propuesto | P15: =IF(J15="Cerrado",IF(AND(K15<>"",M15<>"",N15<>"",ISNUMBER(O15)),"Cierre documentado","Falta evidencia o aceptación"),"Pendiente") -> Pendiente
A16: 2.05 | B16: TRANSVERSAL | C16: Configurar trazabilidad de pruebas y tickets | D16: Repositorio, IDs y enlaces comunes | E16: LZ | F16: LZ | G16: 1.06 | H16: Semana 1 | I16: Un GAP se vincula a WBS, caso, defecto, evidencia y decisión. | J16: Propuesto | P16: =IF(J16="Cerrado",IF(AND(K16<>"",M16<>"",N16<>"",ISNUMBER(O16)),"Cierre documentado","Falta evidencia o aceptación"),"Pendiente") -> Pendiente
A17: 2.06 | B17: TRANSVERSAL | C17: Acordar contingencia y recuperación | D17: Runbook de corte/retorno y conciliación documental | E17: IT | F17: IT | G17: 2.02;2.03 | H17: Antes del piloto | I17: Procedimiento practicable sin duplicar operaciones ni borrar historia. | J17: Propuesto | P17: =IF(J17="Cerrado",IF(AND(K17<>"",M17<>"",N17<>"",ISNUMBER(O17)),"Cierre documentado","Falta evidencia o aceptación"),"Pendiente") -> Pendiente
A18: 2.07 | B18: TRANSVERSAL | C18: Acordar cobertura y objetivos de soporte | D18: Acuerdo horario, prioridades y objetivos de atención | E18: MD | F18: SP | G18: 1.04 | H18: Antes del piloto | I18: DIARCO y Zeetrex validan ventanas, contactos y objetivos. No hay SLA implícito. | J18: Propuesto | P18: =IF(J18="Cerrado",IF(AND(K18<>"",M18<>"",N18<>"",ISNUMBER(O18)),"Cierre documentado","Falta evidencia o aceptación"),"Pendiente") -> Pendiente
... A121: 2.21 | B121: TRANSVERSAL | C121: Preparar seguimiento de competencia y adopción | D121: Registro de aptitud, brechas, repruebas, consultas y acciones por población. | E121: CMZ | F121: LZ | G121: 2.20 | H121: Antes de G1 y por oleada | I121: Instrumentos acordados; asistencia y competencia se registran por separado. | J121: Propuesto | P121: =IF(J121="Cerrado",IF(AND(K121<>"",M121<>"",N121<>"",ISNUMBER(O121)),"Cierre documentado","Falta evidencia o aceptación"),"Pendiente") -> Pendiente

Sheet RACI
A2: Responsabilidades por actividad
A3: Un solo A por fila. DP/RF corresponden al módulo. Nombres y facultades deben confirmarse.
A5: ID | B5: Actividad | C5: SP | D5: LD | E5: DP | F5: RF | G5: US | H5: MD | I5: IT | J5: LZ | K5: ZF | L5: ZT | M5: EXT | N5: CIO | O5: CMZ
A6: RC01 | B6: Asignar personas y tiempo DIARCO | C6: A | D6: R | E6: C | H6: C | I6: C | J6: C | N6: R | O6: I
A7: RC02 | B7: Aprobar baseline de alcance B1 | C7: A | D7: R | E7: C | F7: I | H7: I | I7: I | J7: R | K7: C | L7: C | N7: C | O7: I
A8: RC03 | B8: Definir reglas y datos esperados del módulo | D8: I | E8: A | F8: R | I8: C | J8: I | K8: C | N8: I | O8: I
A9: RC04 | B9: Configurar y entregar versión para prueba | D9: I | E9: I | F9: C | I9: C | J9: A | K9: R | L9: R | N9: I | O9: I
A10: RC05 | B10: Habilitar accesos y entorno DIARCO | D10: I | F10: C | H10: C | I10: A/R | J10: I | L10: C | N10: C | O10: I
A11: RC06 | B11: Certificar datos de negocio | D11: I | E11: A | F11: R | I11: C | J11: I | K11: C | L11: C | N11: C | O11: I
A12: RC07 | B12: Preparar material y formar referentes | D12: I | E12: I | F12: C | H12: C | I12: C | J12: A | K12: R | N12: I | O12: R
A13: RC08 | B13: Validar competencia de referentes | D13: I | E13: A | F13: R | G13: R | H13: C | J13: I | K13: C | N13: I | O13: C
A14: RC09 | B14: Ejecutar UAT y aceptar módulo | D14: I | E14: A | F14: R | G14: R | I14: C | J14: I | K14: C | L14: C | N14: I | O14: C
A15: RC10 | B15: Corregir defecto de producto | D15: I | E15: I | F15: C | H15: I | I15: C | J15: A | K15: C | L15: R | N15: I | O15: I
A16: RC11 | B16: Ejecutar piloto funcional | D16: I | E16: A | F16: R | G16: R | H16: C | I16: C | J16: I | K16: C | N16: I | O16: C
A17: RC12 | B17: Autorizar salida de oleada | C17: A | D17: R | E17: C | F17: I | G17: I | H17: C | I17: C | J17: R | L17: C | N17: C | O17: C
A18: RC13 | B18: Ejecutar corte técnico coordinado | D18: C | E18: I | F18: C | H18: I | I18: A/R | J18: C | L18: R | M18: C | N18: C | O18: I
A19: RC14 | B19: Decidir contingencia o retorno | C19: A | D19: R | E19: C | F19: I | G19: I | H19: C | I19: R | J19: R | L19: C | N19: C | O19: I
A20: RC15 | B20: Registrar y seguir ticket L1 | D20: I | F20: C | H20: A/R | I20: C | N20: I | O20: C
A21: RC16 | B21: Resolver consulta funcional L1 | E21: A | F21: R | G21: I | H21: C | K21: C | N21: I | O21: C
A22: RC17 | B22: Resolver incidente de infraestructura DIARCO | D22: I | H22: C | I22: A/R | J22: I | L22: C | M22: C | N22: C | O22: I
A23: RC18 | B23: Resolver incidente producto L2 | D23: I | E23: I | F23: C | H23: C | I23: C | J23: A | K23: C | L23: R | N23: C | O23: I
A24: RC19 | B24: Capacitar resto de usuarios DIARCO | D24: C | E24: A | F24: R | H24: I | I24: I | K24: C | N24: I | O24: R
A25: RC20 | B25: Aceptar operación y cierre | C25: A | D25: R | E25: C | F25: C | G25: I | H25: C | I25: C | J25: R | N25: C | O25: C
A26: RC21 | B26: Consolidar aprendizajes reutilizables | C26: I | D26: C | E26: C | F26: C | H26: C | I26: C | J26: A | K26: R | L26: R | N26: I | O26: R
A27: RC22 | B27: Asignar equipo IT DIARCO y cobertura | C27: A | D27: R | E27: I | F27: I | G27: I | H27: C | I27: R | J27: C | K27: I | L27: I | M27: I | N27: R | O27: I
A28: RC23 | B28: Planificar formación, prácticas y adopción | C28: I | D28: C | E28: C | F28: C | G28: I | H28: C | I28: I | J28: A | K28: R | L28: I | M28: I | N28: I | O28: R
A29: RC24 | B29: Acordar titular técnico L2 por circuito | C29: I | D29: C | E29: I | F29: I | G29: I | H29: C | I29: C | J29: A | K29: I | L29: R | M29: C | N29: C | O29: I

Sheet GAPS
A2: GAPS y decisiones de alcance
A3: Clasificación inicial basada en antecedentes. Decisión final y evidencia a completar.
A5: GAP | B5: Módulo | C5: Capacidad / pedido | D5: Clasificación documentada | E5: Condición / detalle pendiente | F5: Fuentes | G5: Decisión final | H5: Dueño de decisión | I5: Fecha | J5: Motivo / impacto | K5: Evidencia
A6: GAP-01 | B6: M03 | C6: Reglas y descuentos en listas por sitio/grupo | D6: Pendiente | E6: Semántica y casos dorados | F6: S06
A7: GAP-02 | B7: M04 | C7: Aprobación automática por días de stock/monto | D7: Pendiente | E7: Umbral, autoridad y excepciones sin cerrar | F7: S06
A8: GAP-03 | B8: M05 | C8: OC madre e hijas desde recepción | D8: B1 documentado, reglas por cerrar | E8: S16 documenta validación OC madre/PDA. Confirmar vigencia/cambio de lista y saldo antes de aceptarla. | F8: S06; S16
A9: GAP-04 | B9: M08 | C9: Redespacho y retorno de Valkimia | D9: B1 documentado, contrato pendiente | E9: Redespacho prioritario documentado. Verificar devolución VKM comprometida 27/10 y distinguir preparado/despachado/no preparado. | F9: S06; S07; S16; S17
A10: GAP-05 | B10: M08 | C10: Optimización avanzada TMS/cubicaje/camiones | D10: B2 propuesto | E10: La planificación básica de transferencias es B1 (M09). Optimización avanzada no se agrega a PDD. | F10: S06; S07
A11: GAP-06 | B11: M08 | C11: Cobertura Inventory para cálculo PDD (Dias de Stock y Sobrestock) + Lead Times | D11: B1 detalle pendiente | E11: Revalidar ambiente/cobertura actual. No usar la foto del 29/10 como gate futuro. | F11: S08
A12: GAP-07 | B12: TRANSVERSAL | C12: Precio de venta, márgenes y costos avanzados | D12: B2 según Estrategia | E12: Consolidación posterior: kardex, valorización y precios de venta. No confundir con lista de compra. | F12: S04; S05
A13: GAP-08 | B13: M06 | C13: Recepciones y alcance de convivencia SGM (Fin Despliegue PDA) | D13: B1 detalle pendiente | E13: Confirmar etapa, pilotos y autoridad de stock/pendientes | F13: S05; S06
A14: GAP-09 | B14: M01 | C14: Productos hermanos y sustitutos | D14: Pendiente | E14: Definir resultado observable, consumidor y bloque | F14: S06
A15: GAP-10 | B15: M04 | C15: Migración QX y reposición automática | D15: B2 según Pendientes, ratificar | E15: No confundir uso del sugerido en B1 con cambio del motor/reposición automática legado. | F15: S26
A16: GAP-11 | B16: M06 | C16: Recuperación integral posterior al incidente | D16: B1 prerrequisito | E16: Obtener evidencia de cierre de los compromisos 26–27/10. Autorización, remitos y numeración SGM. | F16: S19; S20; S27
A17: GAP-12 | B17: M07 | C17: Confiabilidad del stock inicial | D17: B1 prerrequisito | E17: Regularizar movimientos antes de interpretar diferencias. Autoridad SGM no equivale a saldo ya conciliado. | F17: S19; S27
A18: GAP-13 | B18: M02 | C18: Modelo final clusters/segmentos | D18: B1 detalle pendiente | E18: Simular categoría real con Liliana. Seis segmentos no son decisión definitiva. | F18: S28

Sheet UAT
A2: Pruebas de aceptación y smoke
A3: Acordar esperado antes de ejecutar. Reprueba: nueva fila con ID propio, conservando la ejecución anterior.
A5: Caso / ejecución | B5: Módulo | C5: Detalle | D5: Escenario | E5: Criticidad | F5: Precondiciones / dataset | G5: Pasos | H5: Resultado esperado a aprobar | I5: R ejecuta | J5: A acepta | K5: Versión | L5: Ambiente | M5: Dataset / corte | N5: Ejecutado por | O5: Fecha ejecución | P5: Resultado real | Q5: Evidencia | R5: Defecto | S5: Dictamen | T5: Aceptado por | U5: Estado ejecución | V5: Control de evidencia | W5: Fecha aceptación | X5: Esperado aprobado por | Y5: Fecha validación esperado
A6: UAT-M01-1 | B6: M01 | C6: =VLOOKUP(T_UAT[[#This Row],[Módulo]],T_Asignaciones[[ID]:[Capacidad B1]],2,FALSE) -> Catálogo y maestros | D6: Alta y cambio autorizados | E6: Crítica | F6: Artículo de prueba con EAN y proveedor válidos | G6: Crear, modificar y consultar en destino | H6: Un solo artículo. Campos críticos y vínculo de sincronización coinciden con el resultado esperado. | I6: RF | J6: DP | U6: No ejecutado | V6: =IF(U6<>"Ejecutado","Sin ejecutar",IF(AND(K6<>"",L6<>"",M6<>"",N6<>"",ISNUMBER(O6),P6<>"",Q6<>"",S6<>"",T6<>"",ISNUMBER(W6),X6<>"",ISNUMBER(Y6)),IF(S6="Aprobado","Ejecución aceptada","Requiere acción"),"Falta evidencia o aceptación")) -> Sin ejecutar
A7: UAT-M01-2 | B7: M01 | C7: =VLOOKUP(T_UAT[[#This Row],[Módulo]],T_Asignaciones[[ID]:[Capacidad B1]],2,FALSE) -> Catálogo y maestros | D7: Identificador duplicado | E7: Crítica | F7: EAN ya asignado a otro artículo | G7: Intentar una nueva alta con ese EAN | H7: Rechazo o tratamiento definido por el contrato, sin duplicar ni sobrescribir el artículo válido. | I7: RF | J7: DP | U7: No ejecutado | V7: =IF(U7<>"Ejecutado","Sin ejecutar",IF(AND(K7<>"",L7<>"",M7<>"",N7<>"",ISNUMBER(O7),P7<>"",Q7<>"",S7<>"",T7<>"",ISNUMBER(W7),X7<>"",ISNUMBER(Y7)),IF(S7="Aprobado","Ejecución aceptada","Requiere acción"),"Falta evidencia o aceptación")) -> Sin ejecutar
A8: UAT-M02-1 | B8: M02 | C8: =VLOOKUP(T_UAT[[#This Row],[Módulo]],T_Asignaciones[[ID]:[Capacidad B1]],2,FALSE) -> Surtido, clusters y segmentos | D8: Par habilitado y excluido | E8: Crítica | F8: Dos pares con distinta elegibilidad y regla vigente | G8: Consultar y ejecutar el consumidor aprobado para ambos | H8: El habilitado participa. El excluido no genera operaciones nuevas incompatibles. Motivo trazable. | I8: RF | J8: DP | U8: No ejecutado | V8: =IF(U8<>"Ejecutado","Sin ejecutar",IF(AND(K8<>"",L8<>"",M8<>"",N8<>"",ISNUMBER(O8),P8<>"",Q8<>"",S8<>"",T8<>"",ISNUMBER(W8),X8<>"",ISNUMBER(Y8)),IF(S8="Aprobado","Ejecución aceptada","Requiere acción"),"Falta evidencia o aceptación")) -> Sin ejecutar
A9: UAT-M02-2 | B9: M02 | C9: =VLOOKUP(T_UAT[[#This Row],[Módulo]],T_Asignaciones[[ID]:[Capacidad B1]],2,FALSE) -> Surtido, clusters y segmentos | D9: Cambio de vigencia | E9: Crítica | F9: Regla actual y cambio con vigencia futura | G9: Consultar antes y después del corte en TEST | H9: Cada fecha usa la versión esperada. El cambio no altera documentos históricos. | I9: RF | J9: DP | U9: No ejecutado | V9: =IF(U9<>"Ejecutado","Sin ejecutar",IF(AND(K9<>"",L9<>"",M9<>"",N9<>"",ISNUMBER(O9),P9<>"",Q9<>"",S9<>"",T9<>"",ISNUMBER(W9),X9<>"",ISNUMBER(Y9)),IF(S9="Aprobado","Ejecución aceptada","Requiere acción"),"Falta evidencia o aceptación")) -> Sin ejecutar
A10: UAT-M03-1 | B10: M03 | C10: =VLOOKUP(T_UAT[[#This Row],[Módulo]],T_Asignaciones[[ID]:[Capacidad B1]],2,FALSE) -> Listas y acuerdos comerciales de compra | D10: Lista por proveedor y sucursal | E10: Crítica | F10: Lista general y específica vigente con valores esperados aprobados | G10: Importar y resolver el precio para dos sitios | H10: Se elige la lista correspondiente. Neto OC y estadístico se explican por componentes y versión. | I10: RF | J10: DP | U10: No ejecutado | V10: =IF(U10<>"Ejecutado","Sin ejecutar",IF(AND(K10<>"",L10<>"",M10<>"",N10<>"",ISNUMBER(O10),P10<>"",Q10<>"",S10<>"",T10<>"",ISNUMBER(W10),X10<>"",ISNUMBER(Y10)),IF(S10="Aprobado","Ejecución aceptada","Requiere acción"),"Falta evidencia o aceptación")) -> Sin ejecutar
A11: UAT-M03-2 | B11: M03 | C11: =VLOOKUP(T_UAT[[#This Row],[Módulo]],T_Asignaciones[[ID]:[Capacidad B1]],2,FALSE) -> Listas y acuerdos comerciales de compra | D11: Importación inválida | E11: Crítica | F11: Archivo con artículo inexistente y descuento mal formado | G11: Importar y corregir el archivo | H11: Se identifican las filas rechazadas. No se publica una versión parcial sin el tratamiento explícitamente aprobado. | I11: RF | J11: DP | U11: No ejecutado | V11: =IF(U11<>"Ejecutado","Sin ejecutar",IF(AND(K11<>"",L11<>"",M11<>"",N11<>"",ISNUMBER(O11),P11<>"",Q11<>"",S11<>"",T11<>"",ISNUMBER(W11),X11<>"",ISNUMBER(Y11)),IF(S11="Aprobado","Ejecución aceptada","Requiere acción"),"Falta evidencia o aceptación")) -> Sin ejecutar
A12: UAT-M04-1 | B12: M04 | C12: =VLOOKUP(T_UAT[[#This Row],[Módulo]],T_Asignaciones[[ID]:[Capacidad B1]],2,FALSE) -> Forecast y compra inteligente/directa | D12: Propuesta explicable | E12: Crítica | F12: Corte con demanda, stock y lista certificados | G12: Generar, revisar un artículo y ajustar con motivo | H12: Se identifican entradas y versión. El ajuste conserva autor y motivo. La aprobación respeta la política acordada. | I12: RF | J12: DP | U12: No ejecutado | V12: =IF(U12<>"Ejecutado","Sin ejecutar",IF(AND(K12<>"",L12<>"",M12<>"",N12<>"",ISNUMBER(O12),P12<>"",Q12<>"",S12<>"",T12<>"",ISNUMBER(W12),X12<>"",ISNUMBER(Y12)),IF(S12="Aprobado","Ejecución aceptada","Requiere acción"),"Falta evidencia o aceptación")) -> Sin ejecutar
A13: UAT-M04-2 | B13: M04 | C13: =VLOOKUP(T_UAT[[#This Row],[Módulo]],T_Asignaciones[[ID]:[Capacidad B1]],2,FALSE) -> Forecast y compra inteligente/directa | D13: Entrada crítica ausente | E13: Crítica | F13: Par de prueba sin un parámetro necesario | G13: Generar propuesta y consultar la excepción | H13: Se bloquea o excluye según política explícita aprobada. Nunca se presenta un resultado incompleto como válido. | I13: RF | J13: DP | U13: No ejecutado | V13: =IF(U13<>"Ejecutado","Sin ejecutar",IF(AND(K13<>"",L13<>"",M13<>"",N13<>"",ISNUMBER(O13),P13<>"",Q13<>"",S13<>"",T13<>"",ISNUMBER(W13),X13<>"",ISNUMBER(Y13)),IF(S13="Aprobado","Ejecución aceptada","Requiere acción"),"Falta evidencia o aceptación")) -> Sin ejecutar
A14: UAT-M05-1 | B14: M05 | C14: =VLOOKUP(T_UAT[[#This Row],[Módulo]],T_Asignaciones[[ID]:[Capacidad B1]],2,FALSE) -> Órdenes de compra e integración SGM | D14: OC aprobada a SGM | E14: Crítica | F14: Comprador/aprobador distintos y OC con cálculo esperado | G14: Generar, aprobar, transmitir y conciliar | H14: Cabecera y líneas coinciden con la versión aprobada. Identificadores vinculados y acuse funcional registrado. SGM no requiere segunda autorización de una OC aprobada en Connexa. | I14: RF | J14: DP | U14: No ejecutado | V14: =IF(U14<>"Ejecutado","Sin ejecutar",IF(AND(K14<>"",L14<>"",M14<>"",N14<>"",ISNUMBER(O14),P14<>"",Q14<>"",S14<>"",T14<>"",ISNUMBER(W14),X14<>"",ISNUMBER(Y14)),IF(S14="Aprobado","Ejecución aceptada","Requiere acción"),"Falta evidencia o aceptación")) -> Sin ejecutar
A15: UAT-M05-2 | B15: M05 | C15: =VLOOKUP(T_UAT[[#This Row],[Módulo]],T_Asignaciones[[ID]:[Capacidad B1]],2,FALSE) -> Órdenes de compra e integración SGM | D15: Reintento de integración | E15: Crítica | F15: OC ya transmitida con acuse perdido en entorno de prueba | G15: Repetir por procedimiento autorizado y consultar destino | H15: Se recupera el estado de una única OC. No hay doble documento ni doble comunicación al proveedor. | I15: RF | J15: DP | U15: No ejecutado | V15: =IF(U15<>"Ejecutado","Sin ejecutar",IF(AND(K15<>"",L15<>"",M15<>"",N15<>"",ISNUMBER(O15),P15<>"",Q15<>"",S15<>"",T15<>"",ISNUMBER(W15),X15<>"",ISNUMBER(Y15)),IF(S15="Aprobado","Ejecución aceptada","Requiere acción"),"Falta evidencia o aceptación")) -> Sin ejecutar
A16: UAT-M06-1 | B16: M06 | C16: =VLOOKUP(T_UAT[[#This Row],[Módulo]],T_Asignaciones[[ID]:[Capacidad B1]],2,FALSE) -> Recepción en sucursal y convivencia SGM | D16: Recepción parcial y diferencia | E16: Crítica | F16: Documento conocido y cantidades físicas certificadas | G16: Recibir parte, registrar diferencia y conciliar | H16: Se registra lo efectivamente recibido y el motivo. Pendiente e impacto se corresponden con el contrato aprobado. | I16: RF | J16: DP | U16: No ejecutado | V16: =IF(U16<>"Ejecutado","Sin ejecutar",IF(AND(K16<>"",L16<>"",M16<>"",N16<>"",ISNUMBER(O16),P16<>"",Q16<>"",S16<>"",T16<>"",ISNUMBER(W16),X16<>"",ISNUMBER(Y16)),IF(S16="Aprobado","Ejecución aceptada","Requiere acción"),"Falta evidencia o aceptación")) -> Sin ejecutar
A17: UAT-M06-2 | B17: M06 | C17: =VLOOKUP(T_UAT[[#This Row],[Módulo]],T_Asignaciones[[ID]:[Capacidad B1]],2,FALSE) -> Recepción en sucursal y convivencia SGM | D17: Falla y recuperación PDA | E17: Crítica | F17: Recepción preparada y comunicación interrumpida en TEST | G17: Recuperar comunicación y seguir el runbook | H17: Una sola recepción efectiva. Operador identifica estado, pendiente y acción autorizada. | I17: RF | J17: DP | U17: No ejecutado | V17: =IF(U17<>"Ejecutado","Sin ejecutar",IF(AND(K17<>"",L17<>"",M17<>"",N17<>"",ISNUMBER(O17),P17<>"",Q17<>"",S17<>"",T17<>"",ISNUMBER(W17),X17<>"",ISNUMBER(Y17)),IF(S17="Aprobado","Ejecución aceptada","Requiere acción"),"Falta evidencia o aceptación")) -> Sin ejecutar
... A25: UAT-M10-2 | B25: M10 | C25: =VLOOKUP(T_UAT[[#This Row],[Módulo]],T_Asignaciones[[ID]:[Capacidad B1]],2,FALSE) -> Stock, conciliación y observabilidad | D25: Alerta y recuperación | E25: Crítica | F25: Falla controlada y canal de atención habilitado | G25: Detectar, clasificar, recuperar y conciliar | H25: Responsables reciben y atienden la alerta. Recuperación confirma documentos y saldos antes de reanudar. | I25: RF | J25: DP | U25: No ejecutado | V25: =IF(U25<>"Ejecutado","Sin ejecutar",IF(AND(K25<>"",L25<>"",M25<>"",N25<>"",ISNUMBER(O25),P25<>"",Q25<>"",S25<>"",T25<>"",ISNUMBER(W25),X25<>"",ISNUMBER(Y25)),IF(S25="Aprobado","Ejecución aceptada","Requiere acción"),"Falta evidencia o aceptación")) -> Sin ejecutar
A26: UAT-E2E-01 | B26: TRANSVERSAL | D26: Catálogo a OC conciliada | E26: Crítica | F26: Módulos M01 a M05 incluidos, datos certificados y esperado aprobado | G26: Aplicar dato, surtido, lista, propuesta y OC. Aprobar y verificar SGM | H26: Identidad, elegibilidad, cantidad y valor coherentes de extremo a extremo. Una única OC vinculada. | I26: RF | J26: DP | U26: No ejecutado | V26: =IF(U26<>"Ejecutado","Sin ejecutar",IF(AND(K26<>"",L26<>"",M26<>"",N26<>"",ISNUMBER(O26),P26<>"",Q26<>"",S26<>"",T26<>"",ISNUMBER(W26),X26<>"",ISNUMBER(Y26)),IF(S26="Aprobado","Ejecución aceptada","Requiere acción"),"Falta evidencia o aceptación")) -> Sin ejecutar
A27: UAT-E2E-02 | B27: TRANSVERSAL | D27: Contingencia y recuperación | E27: Crítica | F27: Punto de interrupción controlado en TEST, autorización de IT y esperado | G27: Interrumpir interfaz, abrir ticket, recuperar y conciliar documentos en vuelo | H27: No hay pérdida ni duplicación. Saldo y documentos conciliados antes de reanudar. | I27: RF | J27: DP | U27: No ejecutado | V27: =IF(U27<>"Ejecutado","Sin ejecutar",IF(AND(K27<>"",L27<>"",M27<>"",N27<>"",ISNUMBER(O27),P27<>"",Q27<>"",S27<>"",T27<>"",ISNUMBER(W27),X27<>"",ISNUMBER(Y27)),IF(S27="Aprobado","Ejecución aceptada","Requiere acción"),"Falta evidencia o aceptación")) -> Sin ejecutar
A28: UAT-SEG-01 | B28: TRANSVERSAL | D28: Permisos y segregación | E28: Crítica | F28: Matriz de permisos aprobada, usuario autorizado y usuario sin facultad | G28: Ejecutar alta/aprobación con ambos usuarios en el circuito incluido | H28: Sólo el autorizado puede actuar. Intentos indebidos se rechazan y auditan. | I28: RF | J28: DP | U28: No ejecutado | V28: =IF(U28<>"Ejecutado","Sin ejecutar",IF(AND(K28<>"",L28<>"",M28<>"",N28<>"",ISNUMBER(O28),P28<>"",Q28<>"",S28<>"",T28<>"",ISNUMBER(W28),X28<>"",ISNUMBER(Y28)),IF(S28="Aprobado","Ejecución aceptada","Requiere acción"),"Falta evidencia o aceptación")) -> Sin ejecutar
A29: UAT-SOP-01 | B29: TRANSVERSAL | D29: Simulacro de soporte | E29: Crítica | F29: Mesa de ayuda, IT, referente y L2 identificados con horario acordado | G29: Registrar problema, clasificar, derivar, comunicar y confirmar solución | H29: Ticket conserva dueño, tiempos y evidencia. Usuario confirma recuperación y actualización de FAQ. | I29: RF | J29: DP | U29: No ejecutado | V29: =IF(U29<>"Ejecutado","Sin ejecutar",IF(AND(K29<>"",L29<>"",M29<>"",N29<>"",ISNUMBER(O29),P29<>"",Q29<>"",S29<>"",T29<>"",ISNUMBER(W29),X29<>"",ISNUMBER(Y29)),IF(S29="Aprobado","Ejecución aceptada","Requiere acción"),"Falta evidencia o aceptación")) -> Sin ejecutar
A30: SMK-01 | B30: TRANSVERSAL | D30: Smoke de flujo productivo controlado | E30: Crítica | F30: Módulo incluido, versión y usuarios habilitados, control de efectos externos | G30: Ingresar con rol, consultar dato vigente, recorrer flujo mínimo, calcular/guardar y verificar estado/acuse autorizado | H30: Flujo mínimo operativo y trazable. No duplica documentos ni comunica al proveedor desde dos sistemas. No equivale a UAT completo. | I30: RF | J30: DP | U30: No ejecutado | V30: =IF(U30<>"Ejecutado","Sin ejecutar",IF(AND(K30<>"",L30<>"",M30<>"",N30<>"",ISNUMBER(O30),P30<>"",Q30<>"",S30<>"",T30<>"",ISNUMBER(W30),X30<>"",ISNUMBER(Y30)),IF(S30="Aprobado","Ejecución aceptada","Requiere acción"),"Falta evidencia o aceptación")) -> Sin ejecutar
A31: UAT-OC-PAR-01 | B31: M05 | C31: =VLOOKUP(T_UAT[[#This Row],[Módulo]],T_Asignaciones[[ID]:[Capacidad B1]],2,FALSE) -> Órdenes de compra e integración SGM | D31: OC valorizada en Connexa y DIARCO/SGM | E31: Crítica | F31: Misma OC vinculada, corte/lista/versiones y cálculo independiente aprobados | G31: Comparar cabecera y cada línea: unidad, cantidad, precio, descuentos, internos, IVA, redondeos y total | H31: Diferencia por campo registrada. Cumple tolerancias aprobadas. DIARCO/SGM sigue válido durante paralelo. | I31: RF | J31: DP | U31: No ejecutado | V31: =IF(U31<>"Ejecutado","Sin ejecutar",IF(AND(K31<>"",L31<>"",M31<>"",N31<>"",ISNUMBER(O31),P31<>"",Q31<>"",S31<>"",T31<>"",ISNUMBER(W31),X31<>"",ISNUMBER(Y31)),IF(S31="Aprobado","Ejecución aceptada","Requiere acción"),"Falta evidencia o aceptación")) -> Sin ejecutar
A32: UAT-OC-PAR-02 | B32: M05 | C32: =VLOOKUP(T_UAT[[#This Row],[Módulo]],T_Asignaciones[[ID]:[Capacidad B1]],2,FALSE) -> Órdenes de compra e integración SGM | D32: Diferencia de valorización fuera de tolerancia | E32: Crítica | F32: OC de prueba con desvío controlado, sin efecto sobre proveedor | G32: Comparar, registrar causa/dueño, corregir configuración o dato y repetir | H32: No se acepta el módulo por coincidencia parcial o por totales compensados. No se sobreescribe la información oficial para hacer coincidir resultados. | I32: RF | J32: DP | U32: No ejecutado | V32: =IF(U32<>"Ejecutado","Sin ejecutar",IF(AND(K32<>"",L32<>"",M32<>"",N32<>"",ISNUMBER(O32),P32<>"",Q32<>"",S32<>"",T32<>"",ISNUMBER(W32),X32<>"",ISNUMBER(Y32)),IF(S32="Aprobado","Ejecución aceptada","Requiere acción"),"Falta evidencia o aceptación")) -> Sin ejecutar
A33: UAT-M05-3 | B33: M05 | C33: =VLOOKUP(T_UAT[[#This Row],[Módulo]],T_Asignaciones[[ID]:[Capacidad B1]],2,FALSE) -> Órdenes de compra e integración SGM | D33: OC madre e hija por PDA | E33: Crítica | F33: Madre y esperado de saldo/vigencia aprobados. Recepción y usuario autorizados | G33: Recibir parcialmente, generar hija, conciliar saldo y probar sobre-recepción | H33: Hija ligada a madre por cantidad recibida. Saldo consume una vez. Exceso bloqueado. Sin duplicar recepción. | I33: RF | J33: DP | U33: No ejecutado | V33: =IF(U33<>"Ejecutado","Sin ejecutar",IF(AND(K33<>"",L33<>"",M33<>"",N33<>"",ISNUMBER(O33),P33<>"",Q33<>"",S33<>"",T33<>"",ISNUMBER(W33),X33<>"",ISNUMBER(Y33)),IF(S33="Aprobado","Ejecución aceptada","Requiere acción"),"Falta evidencia o aceptación")) -> Sin ejecutar
A34: UAT-M09-3 | B34: M09 | C34: =VLOOKUP(T_UAT[[#This Row],[Módulo]],T_Asignaciones[[ID]:[Capacidad B1]],2,FALSE) -> Transferencias y distribución con Valkimia | D34: Redespacho prioritario sin doble preparación | E34: Crítica | F34: Contrato VKM acordado para preparado/despachado/no preparado | G34: Procesar retorno parcial y validar el pendiente/redespacho | H34: La mercadería preparada no despachada conserva identidad y prioridad definida. No se vuelve a preparar por duplicación. | I34: RF | J34: DP | U34: No ejecutado | V34: =IF(U34<>"Ejecutado","Sin ejecutar",IF(AND(K34<>"",L34<>"",M34<>"",N34<>"",ISNUMBER(O34),P34<>"",Q34<>"",S34<>"",T34<>"",ISNUMBER(W34),X34<>"",ISNUMBER(Y34)),IF(S34="Aprobado","Ejecución aceptada","Requiere acción"),"Falta evidencia o aceptación")) -> Sin ejecutar
A35: UAT-M05-4 | B35: M05 | C35: =VLOOKUP(T_UAT[[#This Row],[Módulo]],T_Asignaciones[[ID]:[Capacidad B1]],2,FALSE) -> Órdenes de compra e integración SGM | D35: Recepciones simultáneas contra OC madre | E35: Crítica | F35: Madre con saldo limitado y dos sucursales/operadores de prueba | G35: Intentar consumos simultáneos cuya suma supera saldo | H35: Nunca se excede cantidad autorizada. Ganador/rechazo son trazables y reintentar no duplica consumo. | I35: RF | J35: DP | U35: No ejecutado | V35: =IF(U35<>"Ejecutado","Sin ejecutar",IF(AND(K35<>"",L35<>"",M35<>"",N35<>"",ISNUMBER(O35),P35<>"",Q35<>"",S35<>"",T35<>"",ISNUMBER(W35),X35<>"",ISNUMBER(Y35)),IF(S35="Aprobado","Ejecución aceptada","Requiere acción"),"Falta evidencia o aceptación")) -> Sin ejecutar
A36: UAT-M06-3 | B36: M06 | C36: =VLOOKUP(T_UAT[[#This Row],[Módulo]],T_Asignaciones[[ID]:[Capacidad B1]],2,FALSE) -> Recepción en sucursal y convivencia SGM | D36: Devolución/decomiso con autorización y remito SGM | E36: Crítica | F36: Documento, causa, permisos y esperado aprobados | G36: Registrar, autorizar, sincronizar y consultar procesamiento final SGM | H36: Movimiento, remito y numeración completos una sola vez. Una fila en staging no se acepta como cierre. | I36: RF | J36: DP | U36: No ejecutado | V36: =IF(U36<>"Ejecutado","Sin ejecutar",IF(AND(K36<>"",L36<>"",M36<>"",N36<>"",ISNUMBER(O36),P36<>"",Q36<>"",S36<>"",T36<>"",ISNUMBER(W36),X36<>"",ISNUMBER(Y36)),IF(S36="Aprobado","Ejecución aceptada","Requiere acción"),"Falta evidencia o aceptación")) -> Sin ejecutar
A37: UAT-M07-3 | B37: M07 | C37: =VLOOKUP(T_UAT[[#This Row],[Módulo]],T_Asignaciones[[ID]:[Capacidad B1]],2,FALSE) -> Inventarios y ajustes | D37: Foto inicial y salida de inventario | E37: Crítica | F37: Movimientos pendientes regularizados, mapa/QR y stock SGM de corte | G37: Cargar base, contar con PDA, cerrar, exportar y aplicar según procedimiento | H37: Correspondencia de artículo/ubicación y diferencia explicable. Aplicación en SGM validada por rol autorizado. | I37: RF | J37: DP | U37: No ejecutado | V37: =IF(U37<>"Ejecutado","Sin ejecutar",IF(AND(K37<>"",L37<>"",M37<>"",N37<>"",ISNUMBER(O37),P37<>"",Q37<>"",S37<>"",T37<>"",ISNUMBER(W37),X37<>"",ISNUMBER(Y37)),IF(S37="Aprobado","Ejecución aceptada","Requiere acción"),"Falta evidencia o aceptación")) -> Sin ejecutar
A38: UAT-M10-3 | B38: M10 | C38: =VLOOKUP(T_UAT[[#This Row],[Módulo]],T_Asignaciones[[ID]:[Capacidad B1]],2,FALSE) -> Stock, conciliación y observabilidad | D38: OC/transferencias actualizadas tras reconexión | E38: Crítica | F38: Sincronización habilitada con ventana y latencia acordadas | G38: Cambiar documento de prueba, observar destino y ejecutar carga periódica controlada | H38: Destino se actualiza dentro del acuerdo. Carga posterior no pisa estado válido ni reabre pendientes cerrados. | I38: RF | J38: DP | U38: No ejecutado | V38: =IF(U38<>"Ejecutado","Sin ejecutar",IF(AND(K38<>"",L38<>"",M38<>"",N38<>"",ISNUMBER(O38),P38<>"",Q38<>"",S38<>"",T38<>"",ISNUMBER(W38),X38<>"",ISNUMBER(Y38)),IF(S38="Aprobado","Ejecución aceptada","Requiere acción"),"Falta evidencia o aceptación")) -> Sin ejecutar

Sheet OC paralelo
A2: Comparación de OC valorizada
A3: Duplicar el bloque por OC y línea. El total no compensa diferencias de detalle. DIARCO/SGM mantiene validez en paralelo.
A5: OC / ejecución | B5: Línea / campo | C5: Connexa | D5: DIARCO / SGM (válido) | E5: Esperado independiente | F5: Tolerancia acordada | G5: Diferencia / causa | H5: Dictamen | I5: Responsable | J5: Evidencia | K5: Fecha comparación
B6: Proveedor | H6: Pendiente
B7: Sucursal | H7: Pendiente
B8: Fecha OC / corte | H8: Pendiente
B9: Lista / versión | H9: Pendiente
B10: Moneda | H10: Pendiente
B11: Unidad de compra | H11: Pendiente
B12: Artículo / línea | H12: Pendiente
B13: Cantidad | H13: Pendiente
B14: Precio lista | H14: Pendiente
B15: Descuento / orden de aplicación | H15: Pendiente
B16: Neto OC | H16: Pendiente
B17: Impuestos internos | H17: Pendiente
... B23: Emisor único al proveedor | H23: Pendiente

Sheet Formacion
A2: Competencia y formación en cascada
A3: Agregar usuarios finales por rol. Asistencia y aptitud son registros distintos.
A5: Módulo | B5: Descripcion | C5: Rol | D5: Persona | E5: Qué debe demostrar | F5: Versión / material | G5: Fecha evaluación | H5: Resultado | I5: Brecha / acción | J5: Evaluador | K5: Evidencia | L5: Fecha reprueba
A6: M01 | B6: =VLOOKUP(T_Formacion[[#This Row],[Módulo]],T_Asignaciones[[ID]:[Capacidad B1]],2,FALSE) -> Catálogo y maestros | C6: Titular | E6: Identificadores, unidad/bulto, estados, permisos, sentido de sincronización y prevención de duplicados. | H6: No evaluado
A7: M01 | B7: =VLOOKUP(T_Formacion[[#This Row],[Módulo]],T_Asignaciones[[ID]:[Capacidad B1]],2,FALSE) -> Catálogo y maestros | C7: Suplente | E7: Identificadores, unidad/bulto, estados, permisos, sentido de sincronización y prevención de duplicados. | H7: No evaluado
A8: M02 | B8: =VLOOKUP(T_Formacion[[#This Row],[Módulo]],T_Asignaciones[[ID]:[Capacidad B1]],2,FALSE) -> Surtido, clusters y segmentos | C8: Titular | E8: Diferencias entre cluster, segmento y grupo de sucursales de compra. Herencia, vigencias y estados. | H8: No evaluado
A9: M02 | B9: =VLOOKUP(T_Formacion[[#This Row],[Módulo]],T_Asignaciones[[ID]:[Capacidad B1]],2,FALSE) -> Surtido, clusters y segmentos | C9: Suplente | E9: Diferencias entre cluster, segmento y grupo de sucursales de compra. Herencia, vigencias y estados. | H9: No evaluado
A10: M03 | B10: =VLOOKUP(T_Formacion[[#This Row],[Módulo]],T_Asignaciones[[ID]:[Capacidad B1]],2,FALSE) -> Listas y acuerdos comerciales de compra | C10: Titular | E10: Precio lista, neto OC y neto estadístico. Descuentos y reglas dentro/fuera de OC. Orden de aplicación y vigencia. | H10: No evaluado
A11: M03 | B11: =VLOOKUP(T_Formacion[[#This Row],[Módulo]],T_Asignaciones[[ID]:[Capacidad B1]],2,FALSE) -> Listas y acuerdos comerciales de compra | C11: Suplente | E11: Precio lista, neto OC y neto estadístico. Descuentos y reglas dentro/fuera de OC. Orden de aplicación y vigencia. | H11: No evaluado
A12: M04 | B12: =VLOOKUP(T_Formacion[[#This Row],[Módulo]],T_Asignaciones[[ID]:[Capacidad B1]],2,FALSE) -> Forecast y compra inteligente/directa | C12: Titular | E12: Pronóstico, días de stock, unidades de compra, pendientes, trazabilidad y límites de aprobación. | H12: No evaluado
A13: M04 | B13: =VLOOKUP(T_Formacion[[#This Row],[Módulo]],T_Asignaciones[[ID]:[Capacidad B1]],2,FALSE) -> Forecast y compra inteligente/directa | C13: Suplente | E13: Pronóstico, días de stock, unidades de compra, pendientes, trazabilidad y límites de aprobación. | H13: No evaluado
A14: M05 | B14: =VLOOKUP(T_Formacion[[#This Row],[Módulo]],T_Asignaciones[[ID]:[Capacidad B1]],2,FALSE) -> Órdenes de compra e integración SGM | C14: Titular | E14: Estados de OC, precio/impuestos, permisos, acuse técnico y funcional, reintento y contingencia. | H14: No evaluado
A15: M05 | B15: =VLOOKUP(T_Formacion[[#This Row],[Módulo]],T_Asignaciones[[ID]:[Capacidad B1]],2,FALSE) -> Órdenes de compra e integración SGM | C15: Suplente | E15: Estados de OC, precio/impuestos, permisos, acuse técnico y funcional, reintento y contingencia. | H15: No evaluado
A16: M06 | B16: =VLOOKUP(T_Formacion[[#This Row],[Módulo]],T_Asignaciones[[ID]:[Capacidad B1]],2,FALSE) -> Recepción en sucursal y convivencia SGM | C16: Titular | E16: OC/transferencia pendiente, unidad de recepción, recepción parcial y final, diferencias y contingencia. | H16: No evaluado
A17: M06 | B17: =VLOOKUP(T_Formacion[[#This Row],[Módulo]],T_Asignaciones[[ID]:[Capacidad B1]],2,FALSE) -> Recepción en sucursal y convivencia SGM | C17: Suplente | E17: OC/transferencia pendiente, unidad de recepción, recepción parcial y final, diferencias y contingencia. | H17: No evaluado
... A25: M10 | B25: =VLOOKUP(T_Formacion[[#This Row],[Módulo]],T_Asignaciones[[ID]:[Capacidad B1]],2,FALSE) -> Stock, conciliación y observabilidad | C25: Suplente | E25: Stock oficial frente a proyecciones, cortes, correlación, conciliación y límites del reproceso. | H25: No evaluado
A26: TRANSVERSAL | B26: =VLOOKUP(T_Formacion[[#This Row],[Módulo]],T_Asignaciones[[ID]:[Capacidad B1]],2,FALSE) -> #N/A | C26: CMZ | D26: Pablo Duplessy (propuesto) | E26: Planificar sesiones y práctica, seguir aptitud y brechas sin confundir asistencia con competencia. | H26: No evaluado
A27: TRANSVERSAL | B27: =VLOOKUP(T_Formacion[[#This Row],[Módulo]],T_Asignaciones[[ID]:[Capacidad B1]],2,FALSE) -> #N/A | C27: CIO | D27: Guillermo Añaños (propuesto) | E27: Acordar equipo IT operativo, cobertura y vía de escalación para cada ventana. | H27: No evaluado
A28: TRANSVERSAL | B28: =VLOOKUP(T_Formacion[[#This Row],[Módulo]],T_Asignaciones[[ID]:[Capacidad B1]],2,FALSE) -> #N/A | C28: ZT | D28: Alejandro Ledesma / Eduardo Ettlin (propuestos) | E28: Demostrar integración, diagnóstico L2, recuperación y titular técnico por circuito. | H28: No evaluado

Sheet Decisiones
A2: Decisiones del equipo y Dirección
A3: El silencio no aprueba. Estado Resuelto requiere contenido, decisor, fecha y evidencia.
A5: ID | B5: Decisión requerida | C5: A | D5: Ventana propuesta | E5: Estado | F5: Criterio / contenido | G5: Fuentes | H5: Decisión registrada | I5: Nombre decisor | J5: Fecha decisión | K5: Evidencia
A6: D01 | B6: Detalle B1, GAPS y módulos que entran en paralelo el 04/11 | C6: SP | D6: 30/10 preparación; 02/11 decisión | E6: Sin decidir | F6: Listado final versionado y dueño de cada decisión | G6: S01; S04; S05; S06
A7: D02 | B7: Sponsor y líder DIARCO con facultades | C7: SP | D7: 02/11 | E7: Sin decidir | F7: Nombre, suplente y autoridad explícita | G7: S01; S09
A8: D03 | B8: Titulares, suplentes y horas por módulo | C8: SP | D8: 02/11 | E8: Sin decidir | F8: Persona y jefatura aceptan dedicación protegida | G8: S01; S09
A9: D04 | B9: Mesa de ayuda e IT con cobertura | C9: SP | D9: Semana 1 | E9: Sin decidir | F9: Nombrar líder IT operativo, suplente, guardia por ventana y canal. Confirmar enlace CIO sin confundir ambos roles. | G9: S01; S09; S31
A10: D05 | B10: Población, ciclos y duración del paralelo desde 04/11 | C10: SP | D10: Antes del 04/11 | E10: Sin decidir | F10: Módulos, sitios, usuarios, proveedores, ciclos y exclusiones | G10: S09
A11: D06 | B11: Control de paralelo: autoridad DIARCO/SGM y emisor único | C11: DP | D11: Antes de UAT | E11: Sin decidir | F11: SGM conserva validez. Definir cómo comparar/reconciliar sin doble efecto ni envío al proveedor. | G11: S05; S09
A12: D07 | B12: Reglas pendientes de compra y OC madre | C12: DP | D12: Antes del caso asociado | E12: Sin decidir | F12: Aprobación única documentada. Confirmar umbral automático, vigencia y cierre de OC madre/abierta según S16/S17. | G12: S06
A13: D08 | B13: Cadencia, escalación y gates | C13: SP | D13: 02/11 | E13: Sin decidir | F13: Plazos de decisión, evidencia y responsables de go/no-go | G13: S09
A14: D09 | B14: Horario y objetivos soporte L1/L2 | C14: SP | D14: Antes del piloto | E14: Sin decidir | F14: Acuerdo DIARCO/Zeetrex, sin presumir servicio 24x7 | G14: S09
A15: D10 | B15: Criterio de aceptación OC valorizada y tolerancias | C15: DP | D15: Antes del 04/11 | E15: Sin decidir | F15: Comparar campos y cálculo esperado independiente. Tolerancias aprobadas antes de ejecutar. | G15: S13; S09
A16: D11 | B16: Evidencia de recuperación y calidad de stock | C16: IT | D16: Antes del paralelo afectado | E16: Sin decidir | F16: Obtener resultado de compromisos 26–27/10, pruebas tienda escuela y base conciliada. | G16: S19; S20; S27
A17: D12 | B17: Secuencia de primeras sucursales, equipos y acompañamiento | C17: LD | D17: Antes de oleadas PDA | E17: Sin decidir | F17: Lista inicial, condición Wi-Fi/PDA por sitio, referentes y cobertura. Sin deducir 43 sucursales listas. | G17: S19
... A19: D14 | B19: Rol CMZ, plan de formación y responsables de adopción | C19: LZ | D19: 02/11, antes de G0 | E19: Sin decidir | F19: Confirmar Pablo Duplessy, agenda, RACI, seguimiento de aptitud y límites frente a DP/RF. | G19: S31; S32

Sheet Gates
A2: Autorización de avance por población
A3: Duplicar gate por módulo/oleada. Validar umbrales. Smoke se exige antes del paralelo y no reemplaza UAT.
A5: Gate | B5: Resultado | C5: Criterio propuesto | D5: A | E5: Evidencia requerida | F5: Módulo / oleada | G5: Versión | H5: Decisión | I5: Nombre decisor | J5: Fecha | K5: Enlace / reservas
A6: G0 | B6: Inicio comprometido | C6: Alcance B1, roles nominales, tiempo autorizado, responsable IT operativo, coordinación CMZ, piloto y soporte asignados. | D6: SP | E6: Acta inicial y decisiones D01 a D05/D08 | H6: Pendiente
A7: G1 | B7: Preparación y UAT | C7: Datos y permisos certificados. 100% casos críticos pasan. Sin defectos críticos/altos abiertos en el circuito. | D7: DP | E7: UAT, casos dorados y ficha de referente | H7: Pendiente
A8: G2 | B8: Piloto aceptado | C8: Dos ciclos completos propuestos, uno con excepción. Conciliación sin diferencias críticas. Contingencia y soporte ensayados. | D8: SP | E8: Informe piloto y actas de dueños | H8: Pendiente
A9: G3 | B9: Oleada autorizada | C9: Usuarios preparados, soporte cubierto, corte/retorno validado por IT y recomendación conjunta. | D9: SP | E9: Acta go/no-go y bitácora | H9: Pendiente
A10: G4 | B10: Operación transferida | C10: Cinco días operativos estables propuestos. L1/titular/suplente demuestran autonomía y pendientes asignados. | D10: SP | E10: Acta de transferencia y métricas | H10: Pendiente

Sheet Riesgos
A2: Riesgos y acciones de mitigación
A3: Revisar cada semana y antes de abrir paralelo/oleada.
A5: ID | B5: Riesgo | C5: Dueño rol | D5: Impacto | E5: Señal / disparador | F5: Respuesta propuesta | G5: Decisión vinculada | H5: Dueño nominal | I5: Fecha acción | J5: Estado | K5: Evidencia
A6: R01 | B6: Personas sin tiempo protegido | C6: SP | D6: Alta | E6: No se ejecutan pruebas en las ventanas pactadas | F6: Asignar horas y suplentes. Reducir módulos concurrentes si falta capacidad. | G6: D03 | J6: Abierto
A7: R02 | B7: Alcance no conciliado entre septiembre y octubre | C7: LZ | D7: Alta | E7: Se usa un pedido como compromiso confirmado | F7: Cerrar D01 y registrar cualquier cambio con impacto. | G7: D01 | J7: Abierto
A8: R03 | B8: Doble carga o doble envío durante convivencia SGM | C8: IT | D8: Alta | E8: Dos sistemas modifican la misma entidad o comunican una OC | F8: Matriz de maestría, emisor único, reintento y conciliación. | G8: D06 | J8: Abierto
A9: R04 | B9: IT o mesa de ayuda ausentes hasta el corte | C9: LD | D9: Alta | E9: No hay canal, suplente o runbook probado | F9: Incluirlos desde G0 y exigir simulacro antes del piloto. | G9: D04 | J9: Abierto
A10: R05 | B10: Aceptación basada en demo/asistencia | C10: DP | D10: Alta | E10: Casos sin esperado, ejecutor o evidencia | F10: UAT independiente y práctica individual. Cerrar con firma del dueño. | G10: D05 | J10: Abierto
A11: R06 | B11: Proveedor externo bloquea el circuito | C11: LZ | D11: Alta | E11: Interfaz/acuse no disponible en prueba | F11: Nombrar responsable externo, pactar contrato y alternativa explícita o recortar oleada. | G11: D05 | J11: Abierto
A12: R07 | B12: Datos o parámetros incompletos | C12: DP | D12: Alta | E12: Cálculo no explicable o exclusiones no revisadas | F12: Certificar datos y remediar con dueño. Revalidar cobertura Inventory cuando aplique. | G12: D01 | J12: Abierto
A13: R08 | B13: Fechas históricas interpretadas como compromiso vigente | C13: SP | D13: Alta | E13: Se exige corte SGM por fecha sin gates | F13: Rebaselinar por evidencia y capacidad. No apagar por calendario. | G13: D06 | J13: Abierto
A14: R09 | B14: Capacitación no llega al resto de usuarios | C14: DP | D14: Media | E14: Sólo referente puede operar | F14: Formación en cascada, evaluación por rol y suplente probado. | G14: D03 | J14: Abierto
A15: R10 | B15: Confundir paralelo productivo con nueva autoridad | C15: IT | D15: Alta | E15: Se cambia stock/pendiente o se duplica emisión al proveedor durante comparación | F15: SGM válido. Identificación cruzada, emisor único y pruebas de no duplicación. | G15: D06 | J15: Abierto
A16: R11 | B16: Stock oficial con movimientos aún no incorporados | C16: DP | D16: Alta | E16: Diferencia de inventario se atribuye a merma sin conciliar registros | F16: Separar autoridad SGM de calidad de saldo. Certificar foto inicial y movimientos antes de concluir. | G16: D11 | J16: Abierto
A17: R12 | B17: Cambio sin agenda ni seguimiento de aptitud | C17: CMZ | D17: Media | E17: Referentes asisten pero no demuestran autonomía; usuarios sin cobertura de formación. | F17: Acordar D14 y registrar práctica, brechas y repruebas por población. | G17: D14 | J17: Abierto
A18: R13 | B18: Enlace CIO sin responsable IT operativo | C18: CIO | D18: Alta | E18: No hay persona IT, suplente o ventana para acceso, interfaz y recuperación. | F18: Cerrar D04 con nombres, horas y cobertura; verificar por circuito antes del paralelo. | G18: D04 | J18: Abierto

Sheet Capacidad
A2: Reserva inicial de agenda por rol
A3: Rangos propuestos, confianza baja. No incluyen operación habitual, guardia ni desplazamiento. No suman personas con roles duplicados.
A5: Código | B5: Rol | C5: Organización | D5: Resultado del rol | E5: h/sem mínimo | F5: h/sem máximo | G5: Cantidad personas | H5: Reserva mínima h | I5: Reserva máxima h | J5: Nota
A6: SP | B6: Sponsor DIARCO | C6: Dirección | D6: Priorizar, asignar capacidad, resolver escalaciones y decidir gates globales. | E6: 1 | F6: 2 | H6: =IF(OR(G6="",E6=""),"n.a.",G6*E6) -> n.a. | I6: =IF(OR(G6="",F6=""),"n.a.",G6*F6) -> n.a. | J6: Propuesta no calibrada. Confirmar personas únicas y carga compartida.
A7: LD | B7: Líder implementación DIARCO | C7: DIARCO | D7: Coordinar áreas, disponibilidad, evidencias y acciones internas. | E7: 12 | F7: 20 | H7: =IF(OR(G7="",E7=""),"n.a.",G7*E7) -> n.a. | I7: =IF(OR(G7="",F7=""),"n.a.",G7*F7) -> n.a. | J7: Propuesta no calibrada. Confirmar personas únicas y carga compartida.
A8: DP | B8: Dueño del proceso por módulo | C8: DIARCO | D8: Decidir reglas, aceptar UAT y asumir el proceso operativo. | E8: 2 | F8: 4 | H8: =IF(OR(G8="",E8=""),"n.a.",G8*E8) -> n.a. | I8: =IF(OR(G8="",F8=""),"n.a.",G8*F8) -> n.a. | J8: Propuesta no calibrada. Confirmar personas únicas y carga compartida.
A9: RF | B9: Referente titular por módulo | C9: DIARCO | D9: Preparar datos, probar, enseñar y resolver consultas funcionales L1. | E9: 6 | F9: 10 | H9: =IF(OR(G9="",E9=""),"n.a.",G9*E9) -> n.a. | I9: =IF(OR(G9="",F9=""),"n.a.",G9*F9) -> n.a. | J9: Propuesta no calibrada. Confirmar personas únicas y carga compartida.
A10: SU | B10: Suplente de referente por módulo | C10: DIARCO | D10: Practicar, sustituir al titular y demostrar autonomía. | E10: 3 | F10: 5 | H10: =IF(OR(G10="",E10=""),"n.a.",G10*E10) -> n.a. | I10: =IF(OR(G10="",F10=""),"n.a.",G10*F10) -> n.a. | J10: Propuesta no calibrada. Confirmar personas únicas y carga compartida.
A11: US | B11: Usuarios piloto por módulo | C11: DIARCO | D11: Ejecutar casos y operación real. Registrar dificultades y resultados. | E11: 2 | F11: 4 | H11: =IF(OR(G11="",E11=""),"n.a.",G11*E11) -> n.a. | I11: =IF(OR(G11="",F11=""),"n.a.",G11*F11) -> n.a. | J11: Propuesta no calibrada. Confirmar personas únicas y carga compartida.
A12: MD | B12: Líder mesa de ayuda | C12: DIARCO | D12: Registrar, clasificar, comunicar y seguir tickets hasta confirmar cierre. | E12: 4 | F12: 8 | H12: =IF(OR(G12="",E12=""),"n.a.",G12*E12) -> n.a. | I12: =IF(OR(G12="",F12=""),"n.a.",G12*F12) -> n.a. | J12: Propuesta no calibrada. Confirmar personas únicas y carga compartida.
A13: IT | B13: Líder IT DIARCO | C13: DIARCO | D13: Accesos, conectividad, operación técnica local y coordinación de incidentes. | E13: 4 | F13: 8 | H13: =IF(OR(G13="",E13=""),"n.a.",G13*E13) -> n.a. | I13: =IF(OR(G13="",F13=""),"n.a.",G13*F13) -> n.a. | J13: Propuesta no calibrada. Confirmar personas únicas y carga compartida.
A14: LZ | B14: Líder implementación Zeetrex | C14: Zeetrex | D14: Plan integrado, dependencias, riesgos y coordinación de entrega. | E14: 12 | F14: 20 | H14: =IF(OR(G14="",E14=""),"n.a.",G14*E14) -> n.a. | I14: =IF(OR(G14="",F14=""),"n.a.",G14*F14) -> n.a. | J14: Eduardo Ettlin propuesto como LZ. Consolidar su carga con ZT si ocupa ambos roles.
A15: ZF | B15: Consultor funcional Zeetrex | C15: Zeetrex | D15: Configurar, formar, asistir UAT y transferir conocimiento. | E15: 8 | F15: 16 | H15: =IF(OR(G15="",E15=""),"n.a.",G15*E15) -> n.a. | I15: =IF(OR(G15="",F15=""),"n.a.",G15*F15) -> n.a. | J15: Propuesta no calibrada. Confirmar personas únicas y carga compartida.
A16: ZT | B16: Líder técnico/soporte L2 Zeetrex | C16: Zeetrex | D16: Correcciones, integración, diagnóstico y escalamiento técnico. | E16: 8 | F16: 16 | H16: =IF(OR(G16="",E16=""),"n.a.",G16*E16) -> n.a. | I16: =IF(OR(G16="",F16=""),"n.a.",G16*F16) -> n.a. | J16: Alejandro Ledesma / Eduardo Ettlin propuestos. Definir titular por circuito; no duplicar horas de Eduardo.
A17: EXT | B17: Responsable de sistema tercero | C17: A designar | D17: Cumplir su interfaz y participar de pruebas/recuperación cuando aplique. | E17: 4 | F17: 8 | H17: =IF(OR(G17="",E17=""),"n.a.",G17*E17) -> n.a. | I17: =IF(OR(G17="",F17=""),"n.a.",G17*F17) -> n.a. | J17: Propuesta no calibrada. Confirmar personas únicas y carga compartida.
... A19: CMZ | B19: Gestión del Cambio Zeetrex | C19: Zeetrex | D19: Coordinar formación, práctica, ciclos de prueba y seguimiento de adopción. | E19: 8 | F19: 16 | H19: =IF(OR(G19="",E19=""),"n.a.",G19*E19) -> n.a. | I19: =IF(OR(G19="",F19=""),"n.a.",G19*F19) -> n.a. | J19: Pablo Duplessy, según Gobierno. Acordar dedicación con LZ.

Sheet Gobierno
A2: Equipo directivo y funciones propuestas
A3: Cargos informados por usuario. Las funciones de proyecto requieren acuerdo.
A5: Persona | B5: Cargo informado | C5: Función propuesta | D5: Estado | E5: Facultad por acordar
A6: Pablo Bertolissio | B6: Gerente General DIARCO | C6: Sponsor operativo DIARCO (SP) | D6: Propuesta a confirmar | E6: Prioridad, capacidad interna y gates operativos
A7: Roberto Goldfarb | B7: Owner DIARCO | C7: Patrocinio institucional y escalación estratégica | D7: Propuesta a confirmar | E7: Respaldo de transformación y conflictos de prioridad de compañía
A8: Daniel Padin | B8: CEO Zeetrex | C8: Sponsor ejecutivo Zeetrex | D8: Propuesta a confirmar | E8: Compromiso de entrega, recursos y escalación de Zeetrex
A9: Guillermo Añaños | B9: CIO DIARCO | C9: Equipo de Dirección de DIARCO Provisto poro Zeetrex | D9: Propuesta a confirmar | E9: Disponibilzar Recursos de IT de DIARCO
A10: Eduardo Ettlin | B10: CTSO Zeetrex | C10: Líder implementación Zeetrex (LZ) | D10: Propuesta a confirmar | E10: Plan integrado y coordinación de ejecución
